
08.Jul 2020 18:16:39 evaluator module error
SavedModel file does not exist at: ./5.0_MODELS_DIR/_4_layers_CNN_/{saved_model.pbtxt|saved_model.pb}
Traceback (most recent call last):
  File ".\_4_evaluation.py", line 70, in evaluate
    classifier = models.load_model(''.join([local_script_settings['models_path'], current_model_name]))
  File "C:\carpeta_p_pycharm\M5_kaggle_accuracy\venv\lib\site-packages\tensorflow\python\keras\saving\save.py", line 189, in load_model
    loader_impl.parse_saved_model(filepath)
  File "C:\carpeta_p_pycharm\M5_kaggle_accuracy\venv\lib\site-packages\tensorflow\python\saved_model\loader_impl.py", line 110, in parse_saved_model
    raise IOError("SavedModel file does not exist at: %s/{%s|%s}" %
OSError: SavedModel file does not exist at: ./5.0_MODELS_DIR/_4_layers_CNN_/{saved_model.pbtxt|saved_model.pb}

08.Jul 2020 18:19:57 evaluator module error
'Sequential' object has no attribute 'loads_weights'
Traceback (most recent call last):
  File ".\_4_evaluation.py", line 76, in evaluate
    classifier.loads_weights(''.join([local_script_settings['models_path'], current_model_name, '_', str(date),
AttributeError: 'Sequential' object has no attribute 'loads_weights'

08.Jul 2020 18:20:53 evaluator module error
'Sequential' object has no attribute 'loads_weights'
Traceback (most recent call last):
  File ".\_4_evaluation.py", line 76, in evaluate
    classifier.loads_weights(''.join([local_script_settings['models_path'], current_model_name, '_', str(date),
AttributeError: 'Sequential' object has no attribute 'loads_weights'
error at folder_for_evaluation generation
error at folder_for_evaluation generation
error at folder_for_evaluation generation
Classification metrics can't handle a mix of multiclass and continuous-multioutput targets
Traceback (most recent call last):
  File ".\_4_evaluation.py", line 107, in evaluate
    print(confusion_matrix(test_set.classes, y_predictions))
  File "C:\carpeta_p_pycharm\M5_kaggle_accuracy\venv\lib\site-packages\sklearn\utils\validation.py", line 73, in inner_f
    return f(**kwargs)
  File "C:\carpeta_p_pycharm\M5_kaggle_accuracy\venv\lib\site-packages\sklearn\metrics\_classification.py", line 276, in confusion_matrix
    y_type, y_true, y_pred = _check_targets(y_true, y_pred)
  File "C:\carpeta_p_pycharm\M5_kaggle_accuracy\venv\lib\site-packages\sklearn\metrics\_classification.py", line 90, in _check_targets
    raise ValueError("Classification metrics can't handle a mix of {0} "
ValueError: Classification metrics can't handle a mix of multiclass and continuous-multioutput targets
Classification metrics can't handle a mix of multiclass and continuous-multioutput targets
Traceback (most recent call last):
  File ".\_4_evaluation.py", line 113, in evaluate
    print(classification_report(test_set.classes, y_predictions, target_names=target_names))
  File "C:\carpeta_p_pycharm\M5_kaggle_accuracy\venv\lib\site-packages\sklearn\utils\validation.py", line 73, in inner_f
    return f(**kwargs)
  File "C:\carpeta_p_pycharm\M5_kaggle_accuracy\venv\lib\site-packages\sklearn\metrics\_classification.py", line 1929, in classification_report
    y_type, y_true, y_pred = _check_targets(y_true, y_pred)
  File "C:\carpeta_p_pycharm\M5_kaggle_accuracy\venv\lib\site-packages\sklearn\metrics\_classification.py", line 90, in _check_targets
    raise ValueError("Classification metrics can't handle a mix of {0} "
ValueError: Classification metrics can't handle a mix of multiclass and continuous-multioutput targets
Shapes of all inputs must match: values[0].shape = [900] != values[1].shape = [900,12] [Op:Pack] name: stack
Traceback (most recent call last):
  File ".\_4_evaluation.py", line 115, in evaluate
    print(tf.math.confusion_matrix(labels=test_set.classes, predictions=y_predictions))
  File "C:\carpeta_p_pycharm\M5_kaggle_accuracy\venv\lib\site-packages\tensorflow\python\ops\confusion_matrix.py", line 192, in confusion_matrix
    indices = array_ops.stack([labels, predictions], axis=1)
  File "C:\carpeta_p_pycharm\M5_kaggle_accuracy\venv\lib\site-packages\tensorflow\python\util\dispatch.py", line 180, in wrapper
    return target(*args, **kwargs)
  File "C:\carpeta_p_pycharm\M5_kaggle_accuracy\venv\lib\site-packages\tensorflow\python\ops\array_ops.py", line 1342, in stack
    return gen_array_ops.pack(values, axis=axis, name=name)
  File "C:\carpeta_p_pycharm\M5_kaggle_accuracy\venv\lib\site-packages\tensorflow\python\ops\gen_array_ops.py", line 6337, in pack
    _ops.raise_from_not_ok_status(e, name)
  File "C:\carpeta_p_pycharm\M5_kaggle_accuracy\venv\lib\site-packages\tensorflow\python\framework\ops.py", line 6653, in raise_from_not_ok_status
    six.raise_from(core._status_to_exception(e.code, message), None)
  File "<string>", line 3, in raise_from
tensorflow.python.framework.errors_impl.InvalidArgumentError: Shapes of all inputs must match: values[0].shape = [900] != values[1].shape = [900,12] [Op:Pack] name: stack
Shapes of all inputs must match: values[0].shape = [900] != values[1].shape = [900,12] [Op:Pack] name: stack
Traceback (most recent call last):
  File ".\_4_evaluation.py", line 115, in evaluate
    print(tf.math.confusion_matrix(labels=test_set.classes, predictions=y_predictions))
  File "C:\carpeta_p_pycharm\M5_kaggle_accuracy\venv\lib\site-packages\tensorflow\python\ops\confusion_matrix.py", line 192, in confusion_matrix
    indices = array_ops.stack([labels, predictions], axis=1)
  File "C:\carpeta_p_pycharm\M5_kaggle_accuracy\venv\lib\site-packages\tensorflow\python\util\dispatch.py", line 180, in wrapper
    return target(*args, **kwargs)
  File "C:\carpeta_p_pycharm\M5_kaggle_accuracy\venv\lib\site-packages\tensorflow\python\ops\array_ops.py", line 1342, in stack
    return gen_array_ops.pack(values, axis=axis, name=name)
  File "C:\carpeta_p_pycharm\M5_kaggle_accuracy\venv\lib\site-packages\tensorflow\python\ops\gen_array_ops.py", line 6337, in pack
    _ops.raise_from_not_ok_status(e, name)
  File "C:\carpeta_p_pycharm\M5_kaggle_accuracy\venv\lib\site-packages\tensorflow\python\framework\ops.py", line 6653, in raise_from_not_ok_status
    six.raise_from(core._status_to_exception(e.code, message), None)
  File "<string>", line 3, in raise_from
tensorflow.python.framework.errors_impl.InvalidArgumentError: Shapes of all inputs must match: values[0].shape = [900] != values[1].shape = [900,12] [Op:Pack] name: stack
Shapes of all inputs must match: values[0].shape = [900] != values[1].shape = [900,12] [Op:Pack] name: stack
Traceback (most recent call last):
  File ".\_4_evaluation.py", line 115, in evaluate
    print(tf.math.confusion_matrix(labels=test_set.classes, predictions=y_predictions))
  File "C:\carpeta_p_pycharm\M5_kaggle_accuracy\venv\lib\site-packages\tensorflow\python\ops\confusion_matrix.py", line 192, in confusion_matrix
    indices = array_ops.stack([labels, predictions], axis=1)
  File "C:\carpeta_p_pycharm\M5_kaggle_accuracy\venv\lib\site-packages\tensorflow\python\util\dispatch.py", line 180, in wrapper
    return target(*args, **kwargs)
  File "C:\carpeta_p_pycharm\M5_kaggle_accuracy\venv\lib\site-packages\tensorflow\python\ops\array_ops.py", line 1342, in stack
    return gen_array_ops.pack(values, axis=axis, name=name)
  File "C:\carpeta_p_pycharm\M5_kaggle_accuracy\venv\lib\site-packages\tensorflow\python\ops\gen_array_ops.py", line 6337, in pack
    _ops.raise_from_not_ok_status(e, name)
  File "C:\carpeta_p_pycharm\M5_kaggle_accuracy\venv\lib\site-packages\tensorflow\python\framework\ops.py", line 6653, in raise_from_not_ok_status
    six.raise_from(core._status_to_exception(e.code, message), None)
  File "<string>", line 3, in raise_from
tensorflow.python.framework.errors_impl.InvalidArgumentError: Shapes of all inputs must match: values[0].shape = [900] != values[1].shape = [900,12] [Op:Pack] name: stack
Shapes of all inputs must match: values[0].shape = [900] != values[1].shape = [900,12] [Op:Pack] name: stack
Traceback (most recent call last):
  File ".\_4_evaluation.py", line 116, in evaluate
    print(tf.math.confusion_matrix(labels=test_set.classes, predictions=y_predictions))
  File "C:\carpeta_p_pycharm\M5_kaggle_accuracy\venv\lib\site-packages\tensorflow\python\ops\confusion_matrix.py", line 192, in confusion_matrix
    indices = array_ops.stack([labels, predictions], axis=1)
  File "C:\carpeta_p_pycharm\M5_kaggle_accuracy\venv\lib\site-packages\tensorflow\python\util\dispatch.py", line 180, in wrapper
    return target(*args, **kwargs)
  File "C:\carpeta_p_pycharm\M5_kaggle_accuracy\venv\lib\site-packages\tensorflow\python\ops\array_ops.py", line 1342, in stack
    return gen_array_ops.pack(values, axis=axis, name=name)
  File "C:\carpeta_p_pycharm\M5_kaggle_accuracy\venv\lib\site-packages\tensorflow\python\ops\gen_array_ops.py", line 6337, in pack
    _ops.raise_from_not_ok_status(e, name)
  File "C:\carpeta_p_pycharm\M5_kaggle_accuracy\venv\lib\site-packages\tensorflow\python\framework\ops.py", line 6653, in raise_from_not_ok_status
    six.raise_from(core._status_to_exception(e.code, message), None)
  File "<string>", line 3, in raise_from
tensorflow.python.framework.errors_impl.InvalidArgumentError: Shapes of all inputs must match: values[0].shape = [900] != values[1].shape = [900,12] [Op:Pack] name: stack
Shapes of all inputs must match: values[0].shape = [900] != values[1].shape = [900,12] [Op:Pack] name: stack
Traceback (most recent call last):
  File ".\_4_evaluation.py", line 116, in evaluate
    print(tf.math.confusion_matrix(labels=test_set.classes, predictions=y_predictions))
  File "C:\carpeta_p_pycharm\M5_kaggle_accuracy\venv\lib\site-packages\tensorflow\python\ops\confusion_matrix.py", line 192, in confusion_matrix
    indices = array_ops.stack([labels, predictions], axis=1)
  File "C:\carpeta_p_pycharm\M5_kaggle_accuracy\venv\lib\site-packages\tensorflow\python\util\dispatch.py", line 180, in wrapper
    return target(*args, **kwargs)
  File "C:\carpeta_p_pycharm\M5_kaggle_accuracy\venv\lib\site-packages\tensorflow\python\ops\array_ops.py", line 1342, in stack
    return gen_array_ops.pack(values, axis=axis, name=name)
  File "C:\carpeta_p_pycharm\M5_kaggle_accuracy\venv\lib\site-packages\tensorflow\python\ops\gen_array_ops.py", line 6337, in pack
    _ops.raise_from_not_ok_status(e, name)
  File "C:\carpeta_p_pycharm\M5_kaggle_accuracy\venv\lib\site-packages\tensorflow\python\framework\ops.py", line 6653, in raise_from_not_ok_status
    six.raise_from(core._status_to_exception(e.code, message), None)
  File "<string>", line 3, in raise_from
tensorflow.python.framework.errors_impl.InvalidArgumentError: Shapes of all inputs must match: values[0].shape = [900] != values[1].shape = [900,12] [Op:Pack] name: stack
Shapes of all inputs must match: values[0].shape = [900] != values[1].shape = [900,12] [Op:Pack] name: stack
Traceback (most recent call last):
  File ".\_4_evaluation.py", line 116, in evaluate
    print(tf.math.confusion_matrix(labels=test_set.classes, predictions=y_predictions))
  File "C:\carpeta_p_pycharm\M5_kaggle_accuracy\venv\lib\site-packages\tensorflow\python\ops\confusion_matrix.py", line 192, in confusion_matrix
    indices = array_ops.stack([labels, predictions], axis=1)
  File "C:\carpeta_p_pycharm\M5_kaggle_accuracy\venv\lib\site-packages\tensorflow\python\util\dispatch.py", line 180, in wrapper
    return target(*args, **kwargs)
  File "C:\carpeta_p_pycharm\M5_kaggle_accuracy\venv\lib\site-packages\tensorflow\python\ops\array_ops.py", line 1342, in stack
    return gen_array_ops.pack(values, axis=axis, name=name)
  File "C:\carpeta_p_pycharm\M5_kaggle_accuracy\venv\lib\site-packages\tensorflow\python\ops\gen_array_ops.py", line 6337, in pack
    _ops.raise_from_not_ok_status(e, name)
  File "C:\carpeta_p_pycharm\M5_kaggle_accuracy\venv\lib\site-packages\tensorflow\python\framework\ops.py", line 6653, in raise_from_not_ok_status
    six.raise_from(core._status_to_exception(e.code, message), None)
  File "<string>", line 3, in raise_from
tensorflow.python.framework.errors_impl.InvalidArgumentError: Shapes of all inputs must match: values[0].shape = [900] != values[1].shape = [900,12] [Op:Pack] name: stack
Shapes of all inputs must match: values[0].shape = [900] != values[1].shape = [900,12] [Op:Pack] name: stack
Traceback (most recent call last):
  File ".\_4_evaluation.py", line 117, in evaluate
    print(tf.math.confusion_matrix(labels=test_set.classes, predictions=y_predictions))
  File "C:\carpeta_p_pycharm\M5_kaggle_accuracy\venv\lib\site-packages\tensorflow\python\ops\confusion_matrix.py", line 192, in confusion_matrix
    indices = array_ops.stack([labels, predictions], axis=1)
  File "C:\carpeta_p_pycharm\M5_kaggle_accuracy\venv\lib\site-packages\tensorflow\python\util\dispatch.py", line 180, in wrapper
    return target(*args, **kwargs)
  File "C:\carpeta_p_pycharm\M5_kaggle_accuracy\venv\lib\site-packages\tensorflow\python\ops\array_ops.py", line 1342, in stack
    return gen_array_ops.pack(values, axis=axis, name=name)
  File "C:\carpeta_p_pycharm\M5_kaggle_accuracy\venv\lib\site-packages\tensorflow\python\ops\gen_array_ops.py", line 6337, in pack
    _ops.raise_from_not_ok_status(e, name)
  File "C:\carpeta_p_pycharm\M5_kaggle_accuracy\venv\lib\site-packages\tensorflow\python\framework\ops.py", line 6653, in raise_from_not_ok_status
    six.raise_from(core._status_to_exception(e.code, message), None)
  File "<string>", line 3, in raise_from
tensorflow.python.framework.errors_impl.InvalidArgumentError: Shapes of all inputs must match: values[0].shape = [900] != values[1].shape = [900,12] [Op:Pack] name: stack
Shapes of all inputs must match: values[0].shape = [900] != values[1].shape = [900,12] [Op:Pack] name: stack
Traceback (most recent call last):
  File ".\_4_evaluation.py", line 117, in evaluate
    print(tf.math.confusion_matrix(labels=test_set.classes, predictions=y_predictions))
  File "C:\carpeta_p_pycharm\M5_kaggle_accuracy\venv\lib\site-packages\tensorflow\python\ops\confusion_matrix.py", line 192, in confusion_matrix
    indices = array_ops.stack([labels, predictions], axis=1)
  File "C:\carpeta_p_pycharm\M5_kaggle_accuracy\venv\lib\site-packages\tensorflow\python\util\dispatch.py", line 180, in wrapper
    return target(*args, **kwargs)
  File "C:\carpeta_p_pycharm\M5_kaggle_accuracy\venv\lib\site-packages\tensorflow\python\ops\array_ops.py", line 1342, in stack
    return gen_array_ops.pack(values, axis=axis, name=name)
  File "C:\carpeta_p_pycharm\M5_kaggle_accuracy\venv\lib\site-packages\tensorflow\python\ops\gen_array_ops.py", line 6337, in pack
    _ops.raise_from_not_ok_status(e, name)
  File "C:\carpeta_p_pycharm\M5_kaggle_accuracy\venv\lib\site-packages\tensorflow\python\framework\ops.py", line 6653, in raise_from_not_ok_status
    six.raise_from(core._status_to_exception(e.code, message), None)
  File "<string>", line 3, in raise_from
tensorflow.python.framework.errors_impl.InvalidArgumentError: Shapes of all inputs must match: values[0].shape = [900] != values[1].shape = [900,12] [Op:Pack] name: stack
confusion_matrix() got an unexpected keyword argument 'target_names'
Traceback (most recent call last):
  File ".\_4_evaluation.py", line 117, in evaluate
    print(tf.math.confusion_matrix(labels=test_set.classes, predictions=y_predictions,
TypeError: confusion_matrix() got an unexpected keyword argument 'target_names'
confusion_matrix() got an unexpected keyword argument 'target_names'
Traceback (most recent call last):
  File ".\_4_evaluation.py", line 117, in evaluate
    print(tf.math.confusion_matrix(labels=test_set.classes, predictions=y_predictions,
TypeError: confusion_matrix() got an unexpected keyword argument 'target_names'
Shapes of all inputs must match: values[0].shape = [900] != values[1].shape = [900,12] [Op:Pack] name: stack
Traceback (most recent call last):
  File ".\_4_evaluation.py", line 117, in evaluate
    print(tf.math.confusion_matrix(labels=test_set.classes, predictions=y_predictions))
  File "C:\carpeta_p_pycharm\M5_kaggle_accuracy\venv\lib\site-packages\tensorflow\python\ops\confusion_matrix.py", line 192, in confusion_matrix
    indices = array_ops.stack([labels, predictions], axis=1)
  File "C:\carpeta_p_pycharm\M5_kaggle_accuracy\venv\lib\site-packages\tensorflow\python\util\dispatch.py", line 180, in wrapper
    return target(*args, **kwargs)
  File "C:\carpeta_p_pycharm\M5_kaggle_accuracy\venv\lib\site-packages\tensorflow\python\ops\array_ops.py", line 1342, in stack
    return gen_array_ops.pack(values, axis=axis, name=name)
  File "C:\carpeta_p_pycharm\M5_kaggle_accuracy\venv\lib\site-packages\tensorflow\python\ops\gen_array_ops.py", line 6337, in pack
    _ops.raise_from_not_ok_status(e, name)
  File "C:\carpeta_p_pycharm\M5_kaggle_accuracy\venv\lib\site-packages\tensorflow\python\framework\ops.py", line 6653, in raise_from_not_ok_status
    six.raise_from(core._status_to_exception(e.code, message), None)
  File "<string>", line 3, in raise_from
tensorflow.python.framework.errors_impl.InvalidArgumentError: Shapes of all inputs must match: values[0].shape = [900] != values[1].shape = [900,12] [Op:Pack] name: stack
Can't convert non-rectangular Python sequence to Tensor.
Traceback (most recent call last):
  File ".\_4_evaluation.py", line 117, in evaluate
    print(tf.math.confusion_matrix(labels=(test_set.classes, target_names), predictions=y_predictions))
  File "C:\carpeta_p_pycharm\M5_kaggle_accuracy\venv\lib\site-packages\tensorflow\python\ops\confusion_matrix.py", line 155, in confusion_matrix
    ops.convert_to_tensor(labels, name='labels'),
  File "C:\carpeta_p_pycharm\M5_kaggle_accuracy\venv\lib\site-packages\tensorflow\python\framework\ops.py", line 1341, in convert_to_tensor
    ret = conversion_func(value, dtype=dtype, name=name, as_ref=as_ref)
  File "C:\carpeta_p_pycharm\M5_kaggle_accuracy\venv\lib\site-packages\tensorflow\python\framework\constant_op.py", line 321, in _constant_tensor_conversion_function
    return constant(v, dtype=dtype, name=name)
  File "C:\carpeta_p_pycharm\M5_kaggle_accuracy\venv\lib\site-packages\tensorflow\python\framework\constant_op.py", line 261, in constant
    return _constant_impl(value, dtype, shape, name, verify_shape=False,
  File "C:\carpeta_p_pycharm\M5_kaggle_accuracy\venv\lib\site-packages\tensorflow\python\framework\constant_op.py", line 270, in _constant_impl
    t = convert_to_eager_tensor(value, ctx, dtype)
  File "C:\carpeta_p_pycharm\M5_kaggle_accuracy\venv\lib\site-packages\tensorflow\python\framework\constant_op.py", line 96, in convert_to_eager_tensor
    return ops.EagerTensor(value, ctx.device_name, dtype)
ValueError: Can't convert non-rectangular Python sequence to Tensor.
error at folder_for_evaluation generation
Shape (900, 2, 12) must have rank 2
Traceback (most recent call last):
  File "C:\carpeta_p_pycharm\M5_kaggle_accuracy\venv\lib\site-packages\tensorflow\python\framework\tensor_shape.py", line 930, in merge_with
    self.assert_same_rank(other)
  File "C:\carpeta_p_pycharm\M5_kaggle_accuracy\venv\lib\site-packages\tensorflow\python\framework\tensor_shape.py", line 984, in assert_same_rank
    raise ValueError("Shapes %s and %s must have the same rank" %
ValueError: Shapes (900, 2, 12) and (None, None) must have the same rank

During handling of the above exception, another exception occurred:

Traceback (most recent call last):
  File "C:\carpeta_p_pycharm\M5_kaggle_accuracy\venv\lib\site-packages\tensorflow\python\framework\tensor_shape.py", line 1015, in with_rank
    return self.merge_with(unknown_shape(rank=rank))
  File "C:\carpeta_p_pycharm\M5_kaggle_accuracy\venv\lib\site-packages\tensorflow\python\framework\tensor_shape.py", line 936, in merge_with
    raise ValueError("Shapes %s and %s are not compatible" % (self, other))
ValueError: Shapes (900, 2, 12) and (None, None) are not compatible

During handling of the above exception, another exception occurred:

Traceback (most recent call last):
  File ".\_4_evaluation.py", line 119, in evaluate
    print(tf.math.confusion_matrix(labels=tf.keras.utils.to_categorical(test_set.classes),
  File "C:\carpeta_p_pycharm\M5_kaggle_accuracy\venv\lib\site-packages\tensorflow\python\ops\confusion_matrix.py", line 195, in confusion_matrix
    cm_sparse = sparse_tensor.SparseTensor(
  File "C:\carpeta_p_pycharm\M5_kaggle_accuracy\venv\lib\site-packages\tensorflow\python\framework\sparse_tensor.py", line 174, in __init__
    indices_shape = indices.shape.with_rank(2)
  File "C:\carpeta_p_pycharm\M5_kaggle_accuracy\venv\lib\site-packages\tensorflow\python\framework\tensor_shape.py", line 1017, in with_rank
    raise ValueError("Shape %s must have rank %d" % (self, rank))
ValueError: Shape (900, 2, 12) must have rank 2
Shape (900, 2, 12) must have rank 2
Traceback (most recent call last):
  File "C:\carpeta_p_pycharm\M5_kaggle_accuracy\venv\lib\site-packages\tensorflow\python\framework\tensor_shape.py", line 930, in merge_with
    self.assert_same_rank(other)
  File "C:\carpeta_p_pycharm\M5_kaggle_accuracy\venv\lib\site-packages\tensorflow\python\framework\tensor_shape.py", line 984, in assert_same_rank
    raise ValueError("Shapes %s and %s must have the same rank" %
ValueError: Shapes (900, 2, 12) and (None, None) must have the same rank

During handling of the above exception, another exception occurred:

Traceback (most recent call last):
  File "C:\carpeta_p_pycharm\M5_kaggle_accuracy\venv\lib\site-packages\tensorflow\python\framework\tensor_shape.py", line 1015, in with_rank
    return self.merge_with(unknown_shape(rank=rank))
  File "C:\carpeta_p_pycharm\M5_kaggle_accuracy\venv\lib\site-packages\tensorflow\python\framework\tensor_shape.py", line 936, in merge_with
    raise ValueError("Shapes %s and %s are not compatible" % (self, other))
ValueError: Shapes (900, 2, 12) and (None, None) are not compatible

During handling of the above exception, another exception occurred:

Traceback (most recent call last):
  File ".\_4_evaluation.py", line 119, in evaluate
    print(tf.math.confusion_matrix(
  File "C:\carpeta_p_pycharm\M5_kaggle_accuracy\venv\lib\site-packages\tensorflow\python\ops\confusion_matrix.py", line 195, in confusion_matrix
    cm_sparse = sparse_tensor.SparseTensor(
  File "C:\carpeta_p_pycharm\M5_kaggle_accuracy\venv\lib\site-packages\tensorflow\python\framework\sparse_tensor.py", line 174, in __init__
    indices_shape = indices.shape.with_rank(2)
  File "C:\carpeta_p_pycharm\M5_kaggle_accuracy\venv\lib\site-packages\tensorflow\python\framework\tensor_shape.py", line 1017, in with_rank
    raise ValueError("Shape %s must have rank %d" % (self, rank))
ValueError: Shape (900, 2, 12) must have rank 2
Shape (900, 2, 12) must have rank 2
Traceback (most recent call last):
  File "C:\carpeta_p_pycharm\M5_kaggle_accuracy\venv\lib\site-packages\tensorflow\python\framework\tensor_shape.py", line 930, in merge_with
    self.assert_same_rank(other)
  File "C:\carpeta_p_pycharm\M5_kaggle_accuracy\venv\lib\site-packages\tensorflow\python\framework\tensor_shape.py", line 984, in assert_same_rank
    raise ValueError("Shapes %s and %s must have the same rank" %
ValueError: Shapes (900, 2, 12) and (None, None) must have the same rank

During handling of the above exception, another exception occurred:

Traceback (most recent call last):
  File "C:\carpeta_p_pycharm\M5_kaggle_accuracy\venv\lib\site-packages\tensorflow\python\framework\tensor_shape.py", line 1015, in with_rank
    return self.merge_with(unknown_shape(rank=rank))
  File "C:\carpeta_p_pycharm\M5_kaggle_accuracy\venv\lib\site-packages\tensorflow\python\framework\tensor_shape.py", line 936, in merge_with
    raise ValueError("Shapes %s and %s are not compatible" % (self, other))
ValueError: Shapes (900, 2, 12) and (None, None) are not compatible

During handling of the above exception, another exception occurred:

Traceback (most recent call last):
  File ".\_4_evaluation.py", line 119, in evaluate
    print(tf.math.confusion_matrix(
  File "C:\carpeta_p_pycharm\M5_kaggle_accuracy\venv\lib\site-packages\tensorflow\python\ops\confusion_matrix.py", line 195, in confusion_matrix
    cm_sparse = sparse_tensor.SparseTensor(
  File "C:\carpeta_p_pycharm\M5_kaggle_accuracy\venv\lib\site-packages\tensorflow\python\framework\sparse_tensor.py", line 174, in __init__
    indices_shape = indices.shape.with_rank(2)
  File "C:\carpeta_p_pycharm\M5_kaggle_accuracy\venv\lib\site-packages\tensorflow\python\framework\tensor_shape.py", line 1017, in with_rank
    raise ValueError("Shape %s must have rank %d" % (self, rank))
ValueError: Shape (900, 2, 12) must have rank 2
Shape (900, 2, 12) must have rank 2
Traceback (most recent call last):
  File "C:\carpeta_p_pycharm\M5_kaggle_accuracy\venv\lib\site-packages\tensorflow\python\framework\tensor_shape.py", line 930, in merge_with
    self.assert_same_rank(other)
  File "C:\carpeta_p_pycharm\M5_kaggle_accuracy\venv\lib\site-packages\tensorflow\python\framework\tensor_shape.py", line 984, in assert_same_rank
    raise ValueError("Shapes %s and %s must have the same rank" %
ValueError: Shapes (900, 2, 12) and (None, None) must have the same rank

During handling of the above exception, another exception occurred:

Traceback (most recent call last):
  File "C:\carpeta_p_pycharm\M5_kaggle_accuracy\venv\lib\site-packages\tensorflow\python\framework\tensor_shape.py", line 1015, in with_rank
    return self.merge_with(unknown_shape(rank=rank))
  File "C:\carpeta_p_pycharm\M5_kaggle_accuracy\venv\lib\site-packages\tensorflow\python\framework\tensor_shape.py", line 936, in merge_with
    raise ValueError("Shapes %s and %s are not compatible" % (self, other))
ValueError: Shapes (900, 2, 12) and (None, None) are not compatible

During handling of the above exception, another exception occurred:

Traceback (most recent call last):
  File ".\_4_evaluation.py", line 120, in evaluate
    print(tf.math.confusion_matrix(
  File "C:\carpeta_p_pycharm\M5_kaggle_accuracy\venv\lib\site-packages\tensorflow\python\ops\confusion_matrix.py", line 195, in confusion_matrix
    cm_sparse = sparse_tensor.SparseTensor(
  File "C:\carpeta_p_pycharm\M5_kaggle_accuracy\venv\lib\site-packages\tensorflow\python\framework\sparse_tensor.py", line 174, in __init__
    indices_shape = indices.shape.with_rank(2)
  File "C:\carpeta_p_pycharm\M5_kaggle_accuracy\venv\lib\site-packages\tensorflow\python\framework\tensor_shape.py", line 1017, in with_rank
    raise ValueError("Shape %s must have rank %d" % (self, rank))
ValueError: Shape (900, 2, 12) must have rank 2
Shape (900, 2, 12) must have rank 2
Traceback (most recent call last):
  File "C:\carpeta_p_pycharm\M5_kaggle_accuracy\venv\lib\site-packages\tensorflow\python\framework\tensor_shape.py", line 930, in merge_with
    self.assert_same_rank(other)
  File "C:\carpeta_p_pycharm\M5_kaggle_accuracy\venv\lib\site-packages\tensorflow\python\framework\tensor_shape.py", line 984, in assert_same_rank
    raise ValueError("Shapes %s and %s must have the same rank" %
ValueError: Shapes (900, 2, 12) and (None, None) must have the same rank

During handling of the above exception, another exception occurred:

Traceback (most recent call last):
  File "C:\carpeta_p_pycharm\M5_kaggle_accuracy\venv\lib\site-packages\tensorflow\python\framework\tensor_shape.py", line 1015, in with_rank
    return self.merge_with(unknown_shape(rank=rank))
  File "C:\carpeta_p_pycharm\M5_kaggle_accuracy\venv\lib\site-packages\tensorflow\python\framework\tensor_shape.py", line 936, in merge_with
    raise ValueError("Shapes %s and %s are not compatible" % (self, other))
ValueError: Shapes (900, 2, 12) and (None, None) are not compatible

During handling of the above exception, another exception occurred:

Traceback (most recent call last):
  File ".\_4_evaluation.py", line 120, in evaluate
    print(tf.math.confusion_matrix(
  File "C:\carpeta_p_pycharm\M5_kaggle_accuracy\venv\lib\site-packages\tensorflow\python\ops\confusion_matrix.py", line 195, in confusion_matrix
    cm_sparse = sparse_tensor.SparseTensor(
  File "C:\carpeta_p_pycharm\M5_kaggle_accuracy\venv\lib\site-packages\tensorflow\python\framework\sparse_tensor.py", line 174, in __init__
    indices_shape = indices.shape.with_rank(2)
  File "C:\carpeta_p_pycharm\M5_kaggle_accuracy\venv\lib\site-packages\tensorflow\python\framework\tensor_shape.py", line 1017, in with_rank
    raise ValueError("Shape %s must have rank %d" % (self, rank))
ValueError: Shape (900, 2, 12) must have rank 2
Shapes of all inputs must match: values[0].shape = [900] != values[1].shape = [900,12] [Op:Pack] name: stack
Traceback (most recent call last):
  File ".\_4_evaluation.py", line 119, in evaluate
    print(tf.math.confusion_matrix(labels=test_set.classes, predictions=y_predictions))
  File "C:\carpeta_p_pycharm\M5_kaggle_accuracy\venv\lib\site-packages\tensorflow\python\ops\confusion_matrix.py", line 192, in confusion_matrix
    indices = array_ops.stack([labels, predictions], axis=1)
  File "C:\carpeta_p_pycharm\M5_kaggle_accuracy\venv\lib\site-packages\tensorflow\python\util\dispatch.py", line 180, in wrapper
    return target(*args, **kwargs)
  File "C:\carpeta_p_pycharm\M5_kaggle_accuracy\venv\lib\site-packages\tensorflow\python\ops\array_ops.py", line 1342, in stack
    return gen_array_ops.pack(values, axis=axis, name=name)
  File "C:\carpeta_p_pycharm\M5_kaggle_accuracy\venv\lib\site-packages\tensorflow\python\ops\gen_array_ops.py", line 6337, in pack
    _ops.raise_from_not_ok_status(e, name)
  File "C:\carpeta_p_pycharm\M5_kaggle_accuracy\venv\lib\site-packages\tensorflow\python\framework\ops.py", line 6653, in raise_from_not_ok_status
    six.raise_from(core._status_to_exception(e.code, message), None)
  File "<string>", line 3, in raise_from
tensorflow.python.framework.errors_impl.InvalidArgumentError: Shapes of all inputs must match: values[0].shape = [900] != values[1].shape = [900,12] [Op:Pack] name: stack
Shapes of all inputs must match: values[0].shape = [900] != values[1].shape = [900,12,12] [Op:Pack] name: stack
Traceback (most recent call last):
  File ".\_4_evaluation.py", line 119, in evaluate
    print(tf.math.confusion_matrix(
  File "C:\carpeta_p_pycharm\M5_kaggle_accuracy\venv\lib\site-packages\tensorflow\python\ops\confusion_matrix.py", line 192, in confusion_matrix
    indices = array_ops.stack([labels, predictions], axis=1)
  File "C:\carpeta_p_pycharm\M5_kaggle_accuracy\venv\lib\site-packages\tensorflow\python\util\dispatch.py", line 180, in wrapper
    return target(*args, **kwargs)
  File "C:\carpeta_p_pycharm\M5_kaggle_accuracy\venv\lib\site-packages\tensorflow\python\ops\array_ops.py", line 1342, in stack
    return gen_array_ops.pack(values, axis=axis, name=name)
  File "C:\carpeta_p_pycharm\M5_kaggle_accuracy\venv\lib\site-packages\tensorflow\python\ops\gen_array_ops.py", line 6337, in pack
    _ops.raise_from_not_ok_status(e, name)
  File "C:\carpeta_p_pycharm\M5_kaggle_accuracy\venv\lib\site-packages\tensorflow\python\framework\ops.py", line 6653, in raise_from_not_ok_status
    six.raise_from(core._status_to_exception(e.code, message), None)
  File "<string>", line 3, in raise_from
tensorflow.python.framework.errors_impl.InvalidArgumentError: Shapes of all inputs must match: values[0].shape = [900] != values[1].shape = [900,12,12] [Op:Pack] name: stack
int() argument must be a string, a bytes-like object or a number, not 'dict'
Traceback (most recent call last):
  File ".\_4_evaluation.py", line 120, in evaluate
    labels=tf.keras.utils.to_categorical(
  File "C:\carpeta_p_pycharm\M5_kaggle_accuracy\venv\lib\site-packages\tensorflow\python\keras\utils\np_utils.py", line 49, in to_categorical
    y = np.array(y, dtype='int')
TypeError: int() argument must be a string, a bytes-like object or a number, not 'dict'
Attempt to convert a value ({'method_0_compression_0': 0, 'method_0_compression_1': 1, 'method_0_compression_2': 2, 'method_1_compression_0': 3, 'method_1_compression_1': 4, 'method_1_compression_2': 5, 'method_2_compression_0': 6, 'method_2_compression_1': 7, 'method_2_compression_2': 8, 'method_3_compression_0': 9, 'method_3_compression_1': 10, 'method_3_compression_2': 11}) with an unsupported type (<class 'dict'>) to a Tensor.
Traceback (most recent call last):
  File ".\_4_evaluation.py", line 119, in evaluate
    print(tf.math.confusion_matrix(labels=test_set.class_indices, predictions=y_predictions.argmax(axis=1)))
  File "C:\carpeta_p_pycharm\M5_kaggle_accuracy\venv\lib\site-packages\tensorflow\python\ops\confusion_matrix.py", line 155, in confusion_matrix
    ops.convert_to_tensor(labels, name='labels'),
  File "C:\carpeta_p_pycharm\M5_kaggle_accuracy\venv\lib\site-packages\tensorflow\python\framework\ops.py", line 1341, in convert_to_tensor
    ret = conversion_func(value, dtype=dtype, name=name, as_ref=as_ref)
  File "C:\carpeta_p_pycharm\M5_kaggle_accuracy\venv\lib\site-packages\tensorflow\python\framework\constant_op.py", line 321, in _constant_tensor_conversion_function
    return constant(v, dtype=dtype, name=name)
  File "C:\carpeta_p_pycharm\M5_kaggle_accuracy\venv\lib\site-packages\tensorflow\python\framework\constant_op.py", line 261, in constant
    return _constant_impl(value, dtype, shape, name, verify_shape=False,
  File "C:\carpeta_p_pycharm\M5_kaggle_accuracy\venv\lib\site-packages\tensorflow\python\framework\constant_op.py", line 270, in _constant_impl
    t = convert_to_eager_tensor(value, ctx, dtype)
  File "C:\carpeta_p_pycharm\M5_kaggle_accuracy\venv\lib\site-packages\tensorflow\python\framework\constant_op.py", line 96, in convert_to_eager_tensor
    return ops.EagerTensor(value, ctx.device_name, dtype)
ValueError: Attempt to convert a value ({'method_0_compression_0': 0, 'method_0_compression_1': 1, 'method_0_compression_2': 2, 'method_1_compression_0': 3, 'method_1_compression_1': 4, 'method_1_compression_2': 5, 'method_2_compression_0': 6, 'method_2_compression_1': 7, 'method_2_compression_2': 8, 'method_3_compression_0': 9, 'method_3_compression_1': 10, 'method_3_compression_2': 11}) with an unsupported type (<class 'dict'>) to a Tensor.
Classification metrics can't handle a mix of binary and continuous targets
Traceback (most recent call last):
  File ".\_4_evaluation.py", line 132, in evaluate
    print(confusion_matrix(labels, hidden_message_prob))
  File "C:\carpeta_p_pycharm\M5_kaggle_accuracy\venv\lib\site-packages\sklearn\utils\validation.py", line 73, in inner_f
    return f(**kwargs)
  File "C:\carpeta_p_pycharm\M5_kaggle_accuracy\venv\lib\site-packages\sklearn\metrics\_classification.py", line 276, in confusion_matrix
    y_type, y_true, y_pred = _check_targets(y_true, y_pred)
  File "C:\carpeta_p_pycharm\M5_kaggle_accuracy\venv\lib\site-packages\sklearn\metrics\_classification.py", line 90, in _check_targets
    raise ValueError("Classification metrics can't handle a mix of {0} "
ValueError: Classification metrics can't handle a mix of binary and continuous targets
Classification metrics can't handle a mix of binary and continuous targets
Traceback (most recent call last):
  File ".\_4_evaluation.py", line 132, in evaluate
    print(confusion_matrix(labels, hidden_message_prob))
  File "C:\carpeta_p_pycharm\M5_kaggle_accuracy\venv\lib\site-packages\sklearn\utils\validation.py", line 73, in inner_f
    return f(**kwargs)
  File "C:\carpeta_p_pycharm\M5_kaggle_accuracy\venv\lib\site-packages\sklearn\metrics\_classification.py", line 276, in confusion_matrix
    y_type, y_true, y_pred = _check_targets(y_true, y_pred)
  File "C:\carpeta_p_pycharm\M5_kaggle_accuracy\venv\lib\site-packages\sklearn\metrics\_classification.py", line 90, in _check_targets
    raise ValueError("Classification metrics can't handle a mix of {0} "
ValueError: Classification metrics can't handle a mix of binary and continuous targets
Classification metrics can't handle a mix of binary and continuous targets
Traceback (most recent call last):
  File ".\_4_evaluation.py", line 132, in evaluate
    print(confusion_matrix(labels, no_hidden_message_prob))
  File "C:\carpeta_p_pycharm\M5_kaggle_accuracy\venv\lib\site-packages\sklearn\utils\validation.py", line 73, in inner_f
    return f(**kwargs)
  File "C:\carpeta_p_pycharm\M5_kaggle_accuracy\venv\lib\site-packages\sklearn\metrics\_classification.py", line 276, in confusion_matrix
    y_type, y_true, y_pred = _check_targets(y_true, y_pred)
  File "C:\carpeta_p_pycharm\M5_kaggle_accuracy\venv\lib\site-packages\sklearn\metrics\_classification.py", line 90, in _check_targets
    raise ValueError("Classification metrics can't handle a mix of {0} "
ValueError: Classification metrics can't handle a mix of binary and continuous targets
Classification metrics can't handle a mix of binary and continuous targets
Traceback (most recent call last):
  File ".\_4_evaluation.py", line 133, in evaluate
    print(confusion_matrix(labels, no_hidden_message_prob))
  File "C:\carpeta_p_pycharm\M5_kaggle_accuracy\venv\lib\site-packages\sklearn\utils\validation.py", line 73, in inner_f
    return f(**kwargs)
  File "C:\carpeta_p_pycharm\M5_kaggle_accuracy\venv\lib\site-packages\sklearn\metrics\_classification.py", line 276, in confusion_matrix
    y_type, y_true, y_pred = _check_targets(y_true, y_pred)
  File "C:\carpeta_p_pycharm\M5_kaggle_accuracy\venv\lib\site-packages\sklearn\metrics\_classification.py", line 90, in _check_targets
    raise ValueError("Classification metrics can't handle a mix of {0} "
ValueError: Classification metrics can't handle a mix of binary and continuous targets
Classification metrics can't handle a mix of binary and continuous targets
Traceback (most recent call last):
  File ".\_4_evaluation.py", line 135, in evaluate
    print(classification_report(labels, hidden_message_prob, target_names=target_names))
  File "C:\carpeta_p_pycharm\M5_kaggle_accuracy\venv\lib\site-packages\sklearn\utils\validation.py", line 73, in inner_f
    return f(**kwargs)
  File "C:\carpeta_p_pycharm\M5_kaggle_accuracy\venv\lib\site-packages\sklearn\metrics\_classification.py", line 1929, in classification_report
    y_type, y_true, y_pred = _check_targets(y_true, y_pred)
  File "C:\carpeta_p_pycharm\M5_kaggle_accuracy\venv\lib\site-packages\sklearn\metrics\_classification.py", line 90, in _check_targets
    raise ValueError("Classification metrics can't handle a mix of {0} "
ValueError: Classification metrics can't handle a mix of binary and continuous targets
Classification metrics can't handle a mix of binary and continuous targets
Traceback (most recent call last):
  File ".\_4_evaluation.py", line 135, in evaluate
    print(classification_report(labels, hidden_message_prob))
  File "C:\carpeta_p_pycharm\M5_kaggle_accuracy\venv\lib\site-packages\sklearn\utils\validation.py", line 73, in inner_f
    return f(**kwargs)
  File "C:\carpeta_p_pycharm\M5_kaggle_accuracy\venv\lib\site-packages\sklearn\metrics\_classification.py", line 1929, in classification_report
    y_type, y_true, y_pred = _check_targets(y_true, y_pred)
  File "C:\carpeta_p_pycharm\M5_kaggle_accuracy\venv\lib\site-packages\sklearn\metrics\_classification.py", line 90, in _check_targets
    raise ValueError("Classification metrics can't handle a mix of {0} "
ValueError: Classification metrics can't handle a mix of binary and continuous targets

09.Jul 2020 08:02:22 evaluator module error
Unable to open file (unable to open file: name = './5.0_MODELS_DIR/_4_layers_CNN__2020-07-09_weights.h5', errno = 2, error message = 'No such file or directory', flags = 0, o_flags = 0)
Traceback (most recent call last):
  File ".\_4_evaluation.py", line 76, in evaluate
    classifier.load_weights(''.join([local_script_settings['models_path'], current_model_name, '_', str(date),
  File "C:\carpeta_p_pycharm\M5_kaggle_accuracy\venv\lib\site-packages\tensorflow\python\keras\engine\training.py", line 250, in load_weights
    return super(Model, self).load_weights(filepath, by_name, skip_mismatch)
  File "C:\carpeta_p_pycharm\M5_kaggle_accuracy\venv\lib\site-packages\tensorflow\python\keras\engine\network.py", line 1259, in load_weights
    with h5py.File(filepath, 'r') as f:
  File "C:\carpeta_p_pycharm\M5_kaggle_accuracy\venv\lib\site-packages\h5py\_hl\files.py", line 406, in __init__
    fid = make_fid(name, mode, userblock_size,
  File "C:\carpeta_p_pycharm\M5_kaggle_accuracy\venv\lib\site-packages\h5py\_hl\files.py", line 173, in make_fid
    fid = h5f.open(name, flags, fapl=fapl)
  File "h5py\_objects.pyx", line 54, in h5py._objects.with_phil.wrapper
  File "h5py\_objects.pyx", line 55, in h5py._objects.with_phil.wrapper
  File "h5py\h5f.pyx", line 88, in h5py.h5f.open
OSError: Unable to open file (unable to open file: name = './5.0_MODELS_DIR/_4_layers_CNN__2020-07-09_weights.h5', errno = 2, error message = 'No such file or directory', flags = 0, o_flags = 0)

09.Jul 2020 08:14:04 evaluator module error
Unable to open file (unable to open file: name = './5.0_MODELS_DIR/_4_layers_CNN__2020-07-09_weights.h5', errno = 2, error message = 'No such file or directory', flags = 0, o_flags = 0)
Traceback (most recent call last):
  File ".\_4_evaluation.py", line 76, in evaluate
    classifier.load_weights(''.join([local_script_settings['models_path'], current_model_name, '_', str(date),
  File "C:\carpeta_p_pycharm\M5_kaggle_accuracy\venv\lib\site-packages\tensorflow\python\keras\engine\training.py", line 250, in load_weights
    return super(Model, self).load_weights(filepath, by_name, skip_mismatch)
  File "C:\carpeta_p_pycharm\M5_kaggle_accuracy\venv\lib\site-packages\tensorflow\python\keras\engine\network.py", line 1259, in load_weights
    with h5py.File(filepath, 'r') as f:
  File "C:\carpeta_p_pycharm\M5_kaggle_accuracy\venv\lib\site-packages\h5py\_hl\files.py", line 406, in __init__
    fid = make_fid(name, mode, userblock_size,
  File "C:\carpeta_p_pycharm\M5_kaggle_accuracy\venv\lib\site-packages\h5py\_hl\files.py", line 173, in make_fid
    fid = h5f.open(name, flags, fapl=fapl)
  File "h5py\_objects.pyx", line 54, in h5py._objects.with_phil.wrapper
  File "h5py\_objects.pyx", line 55, in h5py._objects.with_phil.wrapper
  File "h5py\h5f.pyx", line 88, in h5py.h5f.open
OSError: Unable to open file (unable to open file: name = './5.0_MODELS_DIR/_4_layers_CNN__2020-07-09_weights.h5', errno = 2, error message = 'No such file or directory', flags = 0, o_flags = 0)

09.Jul 2020 08:15:44 evaluator module error
Unable to open file (unable to open file: name = './5.0_MODELS_DIR/_4_layers_CNN__2020-07-09_weights.h5', errno = 2, error message = 'No such file or directory', flags = 0, o_flags = 0)
Traceback (most recent call last):
  File ".\_4_evaluation.py", line 76, in evaluate
    classifier.load_weights(''.join([local_script_settings['models_path'], current_model_name, '_', str(date),
  File "C:\carpeta_p_pycharm\M5_kaggle_accuracy\venv\lib\site-packages\tensorflow\python\keras\engine\training.py", line 250, in load_weights
    return super(Model, self).load_weights(filepath, by_name, skip_mismatch)
  File "C:\carpeta_p_pycharm\M5_kaggle_accuracy\venv\lib\site-packages\tensorflow\python\keras\engine\network.py", line 1259, in load_weights
    with h5py.File(filepath, 'r') as f:
  File "C:\carpeta_p_pycharm\M5_kaggle_accuracy\venv\lib\site-packages\h5py\_hl\files.py", line 406, in __init__
    fid = make_fid(name, mode, userblock_size,
  File "C:\carpeta_p_pycharm\M5_kaggle_accuracy\venv\lib\site-packages\h5py\_hl\files.py", line 173, in make_fid
    fid = h5f.open(name, flags, fapl=fapl)
  File "h5py\_objects.pyx", line 54, in h5py._objects.with_phil.wrapper
  File "h5py\_objects.pyx", line 55, in h5py._objects.with_phil.wrapper
  File "h5py\h5f.pyx", line 88, in h5py.h5f.open
OSError: Unable to open file (unable to open file: name = './5.0_MODELS_DIR/_4_layers_CNN__2020-07-09_weights.h5', errno = 2, error message = 'No such file or directory', flags = 0, o_flags = 0)

09.Jul 2020 11:25:54 evaluator module error
Shapes (3136, 128) and (64, 128) are incompatible
Traceback (most recent call last):
  File ".\_4_evaluation.py", line 76, in evaluate
    classifier.load_weights(''.join([local_script_settings['models_path'], current_model_name, '_', str(date),
  File "C:\carpeta_p_pycharm\M5_kaggle_accuracy\venv\lib\site-packages\tensorflow\python\keras\engine\training.py", line 250, in load_weights
    return super(Model, self).load_weights(filepath, by_name, skip_mismatch)
  File "C:\carpeta_p_pycharm\M5_kaggle_accuracy\venv\lib\site-packages\tensorflow\python\keras\engine\network.py", line 1266, in load_weights
    hdf5_format.load_weights_from_hdf5_group(f, self.layers)
  File "C:\carpeta_p_pycharm\M5_kaggle_accuracy\venv\lib\site-packages\tensorflow\python\keras\saving\hdf5_format.py", line 707, in load_weights_from_hdf5_group
    K.batch_set_value(weight_value_tuples)
  File "C:\carpeta_p_pycharm\M5_kaggle_accuracy\venv\lib\site-packages\tensorflow\python\keras\backend.py", line 3384, in batch_set_value
    x.assign(np.asarray(value, dtype=dtype(x)))
  File "C:\carpeta_p_pycharm\M5_kaggle_accuracy\venv\lib\site-packages\tensorflow\python\ops\resource_variable_ops.py", line 846, in assign
    self._shape.assert_is_compatible_with(value_tensor.shape)
  File "C:\carpeta_p_pycharm\M5_kaggle_accuracy\venv\lib\site-packages\tensorflow\python\framework\tensor_shape.py", line 1117, in assert_is_compatible_with
    raise ValueError("Shapes %s and %s are incompatible" % (self, other))
ValueError: Shapes (3136, 128) and (64, 128) are incompatible

09.Jul 2020 11:30:41 evaluator module error
Shapes (3136, 128) and (64, 128) are incompatible
Traceback (most recent call last):
  File ".\_4_evaluation.py", line 76, in evaluate
    classifier.load_weights(''.join([local_script_settings['models_path'], current_model_name, '_', str(date),
  File "C:\carpeta_p_pycharm\M5_kaggle_accuracy\venv\lib\site-packages\tensorflow\python\keras\engine\training.py", line 250, in load_weights
    return super(Model, self).load_weights(filepath, by_name, skip_mismatch)
  File "C:\carpeta_p_pycharm\M5_kaggle_accuracy\venv\lib\site-packages\tensorflow\python\keras\engine\network.py", line 1266, in load_weights
    hdf5_format.load_weights_from_hdf5_group(f, self.layers)
  File "C:\carpeta_p_pycharm\M5_kaggle_accuracy\venv\lib\site-packages\tensorflow\python\keras\saving\hdf5_format.py", line 707, in load_weights_from_hdf5_group
    K.batch_set_value(weight_value_tuples)
  File "C:\carpeta_p_pycharm\M5_kaggle_accuracy\venv\lib\site-packages\tensorflow\python\keras\backend.py", line 3384, in batch_set_value
    x.assign(np.asarray(value, dtype=dtype(x)))
  File "C:\carpeta_p_pycharm\M5_kaggle_accuracy\venv\lib\site-packages\tensorflow\python\ops\resource_variable_ops.py", line 846, in assign
    self._shape.assert_is_compatible_with(value_tensor.shape)
  File "C:\carpeta_p_pycharm\M5_kaggle_accuracy\venv\lib\site-packages\tensorflow\python\framework\tensor_shape.py", line 1117, in assert_is_compatible_with
    raise ValueError("Shapes %s and %s are incompatible" % (self, other))
ValueError: Shapes (3136, 128) and (64, 128) are incompatible

09.Jul 2020 11:37:50 evaluator module error
Shapes (3136, 128) and (64, 128) are incompatible
Traceback (most recent call last):
  File ".\_4_evaluation.py", line 76, in evaluate
    classifier.load_weights(''.join([local_script_settings['models_path'], current_model_name, '_', str(date),
  File "C:\carpeta_p_pycharm\M5_kaggle_accuracy\venv\lib\site-packages\tensorflow\python\keras\engine\training.py", line 250, in load_weights
    return super(Model, self).load_weights(filepath, by_name, skip_mismatch)
  File "C:\carpeta_p_pycharm\M5_kaggle_accuracy\venv\lib\site-packages\tensorflow\python\keras\engine\network.py", line 1266, in load_weights
    hdf5_format.load_weights_from_hdf5_group(f, self.layers)
  File "C:\carpeta_p_pycharm\M5_kaggle_accuracy\venv\lib\site-packages\tensorflow\python\keras\saving\hdf5_format.py", line 707, in load_weights_from_hdf5_group
    K.batch_set_value(weight_value_tuples)
  File "C:\carpeta_p_pycharm\M5_kaggle_accuracy\venv\lib\site-packages\tensorflow\python\keras\backend.py", line 3384, in batch_set_value
    x.assign(np.asarray(value, dtype=dtype(x)))
  File "C:\carpeta_p_pycharm\M5_kaggle_accuracy\venv\lib\site-packages\tensorflow\python\ops\resource_variable_ops.py", line 846, in assign
    self._shape.assert_is_compatible_with(value_tensor.shape)
  File "C:\carpeta_p_pycharm\M5_kaggle_accuracy\venv\lib\site-packages\tensorflow\python\framework\tensor_shape.py", line 1117, in assert_is_compatible_with
    raise ValueError("Shapes %s and %s are incompatible" % (self, other))
ValueError: Shapes (3136, 128) and (64, 128) are incompatible

09.Jul 2020 12:31:12 evaluator module error
Shapes (3136, 128) and (64, 128) are incompatible
Traceback (most recent call last):
  File ".\_4_evaluation.py", line 76, in evaluate
    classifier.load_weights(''.join([local_script_settings['models_path'], current_model_name, '_', str(date),
  File "C:\carpeta_p_pycharm\M5_kaggle_accuracy\venv\lib\site-packages\tensorflow\python\keras\engine\training.py", line 250, in load_weights
    return super(Model, self).load_weights(filepath, by_name, skip_mismatch)
  File "C:\carpeta_p_pycharm\M5_kaggle_accuracy\venv\lib\site-packages\tensorflow\python\keras\engine\network.py", line 1266, in load_weights
    hdf5_format.load_weights_from_hdf5_group(f, self.layers)
  File "C:\carpeta_p_pycharm\M5_kaggle_accuracy\venv\lib\site-packages\tensorflow\python\keras\saving\hdf5_format.py", line 707, in load_weights_from_hdf5_group
    K.batch_set_value(weight_value_tuples)
  File "C:\carpeta_p_pycharm\M5_kaggle_accuracy\venv\lib\site-packages\tensorflow\python\keras\backend.py", line 3384, in batch_set_value
    x.assign(np.asarray(value, dtype=dtype(x)))
  File "C:\carpeta_p_pycharm\M5_kaggle_accuracy\venv\lib\site-packages\tensorflow\python\ops\resource_variable_ops.py", line 846, in assign
    self._shape.assert_is_compatible_with(value_tensor.shape)
  File "C:\carpeta_p_pycharm\M5_kaggle_accuracy\venv\lib\site-packages\tensorflow\python\framework\tensor_shape.py", line 1117, in assert_is_compatible_with
    raise ValueError("Shapes %s and %s are incompatible" % (self, other))
ValueError: Shapes (3136, 128) and (64, 128) are incompatible

09.Jul 2020 12:38:20 evaluator module error
Shapes (3136, 128) and (64, 128) are incompatible
Traceback (most recent call last):
  File ".\_4_evaluation.py", line 76, in evaluate
    classifier.load_weights(''.join([local_script_settings['models_path'], current_model_name, '_', str(date),
  File "C:\carpeta_p_pycharm\M5_kaggle_accuracy\venv\lib\site-packages\tensorflow\python\keras\engine\training.py", line 250, in load_weights
    return super(Model, self).load_weights(filepath, by_name, skip_mismatch)
  File "C:\carpeta_p_pycharm\M5_kaggle_accuracy\venv\lib\site-packages\tensorflow\python\keras\engine\network.py", line 1266, in load_weights
    hdf5_format.load_weights_from_hdf5_group(f, self.layers)
  File "C:\carpeta_p_pycharm\M5_kaggle_accuracy\venv\lib\site-packages\tensorflow\python\keras\saving\hdf5_format.py", line 707, in load_weights_from_hdf5_group
    K.batch_set_value(weight_value_tuples)
  File "C:\carpeta_p_pycharm\M5_kaggle_accuracy\venv\lib\site-packages\tensorflow\python\keras\backend.py", line 3384, in batch_set_value
    x.assign(np.asarray(value, dtype=dtype(x)))
  File "C:\carpeta_p_pycharm\M5_kaggle_accuracy\venv\lib\site-packages\tensorflow\python\ops\resource_variable_ops.py", line 846, in assign
    self._shape.assert_is_compatible_with(value_tensor.shape)
  File "C:\carpeta_p_pycharm\M5_kaggle_accuracy\venv\lib\site-packages\tensorflow\python\framework\tensor_shape.py", line 1117, in assert_is_compatible_with
    raise ValueError("Shapes %s and %s are incompatible" % (self, other))
ValueError: Shapes (3136, 128) and (64, 128) are incompatible
2 root error(s) found.
  (0) Invalid argument:  logits and labels must have the same first dimension, got logits shape [16,1] and labels shape [192]
	 [[node sparse_categorical_crossentropy/SparseSoftmaxCrossEntropyWithLogits/SparseSoftmaxCrossEntropyWithLogits (defined at .\_4_evaluation.py:117) ]]
	 [[assert_less_equal/Assert/AssertGuard/pivot_f/_13/_49]]
  (1) Invalid argument:  logits and labels must have the same first dimension, got logits shape [16,1] and labels shape [192]
	 [[node sparse_categorical_crossentropy/SparseSoftmaxCrossEntropyWithLogits/SparseSoftmaxCrossEntropyWithLogits (defined at .\_4_evaluation.py:117) ]]
0 successful operations.
0 derived errors ignored. [Op:__inference_test_function_156471]

Function call stack:
test_function -> test_function
Traceback (most recent call last):
  File ".\_4_evaluation.py", line 117, in evaluate
    print(classifier.evaluate(test_set, verbose=0, return_dict=True))
  File "C:\carpeta_p_pycharm\M5_kaggle_accuracy\venv\lib\site-packages\tensorflow\python\keras\engine\training.py", line 66, in _method_wrapper
    return method(self, *args, **kwargs)
  File "C:\carpeta_p_pycharm\M5_kaggle_accuracy\venv\lib\site-packages\tensorflow\python\keras\engine\training.py", line 1081, in evaluate
    tmp_logs = test_function(iterator)
  File "C:\carpeta_p_pycharm\M5_kaggle_accuracy\venv\lib\site-packages\tensorflow\python\eager\def_function.py", line 580, in __call__
    result = self._call(*args, **kwds)
  File "C:\carpeta_p_pycharm\M5_kaggle_accuracy\venv\lib\site-packages\tensorflow\python\eager\def_function.py", line 650, in _call
    return self._concrete_stateful_fn._filtered_call(canon_args, canon_kwds)  # pylint: disable=protected-access
  File "C:\carpeta_p_pycharm\M5_kaggle_accuracy\venv\lib\site-packages\tensorflow\python\eager\function.py", line 1661, in _filtered_call
    return self._call_flat(
  File "C:\carpeta_p_pycharm\M5_kaggle_accuracy\venv\lib\site-packages\tensorflow\python\eager\function.py", line 1745, in _call_flat
    return self._build_call_outputs(self._inference_function.call(
  File "C:\carpeta_p_pycharm\M5_kaggle_accuracy\venv\lib\site-packages\tensorflow\python\eager\function.py", line 593, in call
    outputs = execute.execute(
  File "C:\carpeta_p_pycharm\M5_kaggle_accuracy\venv\lib\site-packages\tensorflow\python\eager\execute.py", line 59, in quick_execute
    tensors = pywrap_tfe.TFE_Py_Execute(ctx._handle, device_name, op_name,
tensorflow.python.framework.errors_impl.InvalidArgumentError: 2 root error(s) found.
  (0) Invalid argument:  logits and labels must have the same first dimension, got logits shape [16,1] and labels shape [192]
	 [[node sparse_categorical_crossentropy/SparseSoftmaxCrossEntropyWithLogits/SparseSoftmaxCrossEntropyWithLogits (defined at .\_4_evaluation.py:117) ]]
	 [[assert_less_equal/Assert/AssertGuard/pivot_f/_13/_49]]
  (1) Invalid argument:  logits and labels must have the same first dimension, got logits shape [16,1] and labels shape [192]
	 [[node sparse_categorical_crossentropy/SparseSoftmaxCrossEntropyWithLogits/SparseSoftmaxCrossEntropyWithLogits (defined at .\_4_evaluation.py:117) ]]
0 successful operations.
0 derived errors ignored. [Op:__inference_test_function_156471]

Function call stack:
test_function -> test_function

y_true and y_pred contain different number of classes 12, 2. Please provide the true labels explicitly through the labels argument. Classes found in y_true: [ 0  1  2  3  4  5  6  7  8  9 10 11]
Traceback (most recent call last):
  File ".\_4_evaluation.py", line 118, in evaluate
    print("log_loss(sklearn.metrics):", log_loss(np.asarray(test_set.classes), y_predictions, eps=1e-15))
  File "C:\carpeta_p_pycharm\M5_kaggle_accuracy\venv\lib\site-packages\sklearn\utils\validation.py", line 73, in inner_f
    return f(**kwargs)
  File "C:\carpeta_p_pycharm\M5_kaggle_accuracy\venv\lib\site-packages\sklearn\metrics\_classification.py", line 2226, in log_loss
    raise ValueError("y_true and y_pred contain different number of "
ValueError: y_true and y_pred contain different number of classes 12, 2. Please provide the true labels explicitly through the labels argument. Classes found in y_true: [ 0  1  2  3  4  5  6  7  8  9 10 11]

09.Jul 2020 13:06:03 evaluator module error
Shapes (12, 12) and (12, 1) are incompatible
Traceback (most recent call last):
  File ".\_4_evaluation.py", line 76, in evaluate
    classifier.load_weights(''.join([local_script_settings['models_path'], current_model_name, '_', str(date),
  File "C:\carpeta_p_pycharm\M5_kaggle_accuracy\venv\lib\site-packages\tensorflow\python\keras\engine\training.py", line 250, in load_weights
    return super(Model, self).load_weights(filepath, by_name, skip_mismatch)
  File "C:\carpeta_p_pycharm\M5_kaggle_accuracy\venv\lib\site-packages\tensorflow\python\keras\engine\network.py", line 1266, in load_weights
    hdf5_format.load_weights_from_hdf5_group(f, self.layers)
  File "C:\carpeta_p_pycharm\M5_kaggle_accuracy\venv\lib\site-packages\tensorflow\python\keras\saving\hdf5_format.py", line 707, in load_weights_from_hdf5_group
    K.batch_set_value(weight_value_tuples)
  File "C:\carpeta_p_pycharm\M5_kaggle_accuracy\venv\lib\site-packages\tensorflow\python\keras\backend.py", line 3384, in batch_set_value
    x.assign(np.asarray(value, dtype=dtype(x)))
  File "C:\carpeta_p_pycharm\M5_kaggle_accuracy\venv\lib\site-packages\tensorflow\python\ops\resource_variable_ops.py", line 846, in assign
    self._shape.assert_is_compatible_with(value_tensor.shape)
  File "C:\carpeta_p_pycharm\M5_kaggle_accuracy\venv\lib\site-packages\tensorflow\python\framework\tensor_shape.py", line 1117, in assert_is_compatible_with
    raise ValueError("Shapes %s and %s are incompatible" % (self, other))
ValueError: Shapes (12, 12) and (12, 1) are incompatible

09.Jul 2020 13:17:00 evaluator module error
Shapes (12, 12) and (12, 1) are incompatible
Traceback (most recent call last):
  File ".\_4_evaluation.py", line 76, in evaluate
    classifier.load_weights(''.join([local_script_settings['models_path'], current_model_name, '_', str(date),
  File "C:\carpeta_p_pycharm\M5_kaggle_accuracy\venv\lib\site-packages\tensorflow\python\keras\engine\training.py", line 250, in load_weights
    return super(Model, self).load_weights(filepath, by_name, skip_mismatch)
  File "C:\carpeta_p_pycharm\M5_kaggle_accuracy\venv\lib\site-packages\tensorflow\python\keras\engine\network.py", line 1266, in load_weights
    hdf5_format.load_weights_from_hdf5_group(f, self.layers)
  File "C:\carpeta_p_pycharm\M5_kaggle_accuracy\venv\lib\site-packages\tensorflow\python\keras\saving\hdf5_format.py", line 707, in load_weights_from_hdf5_group
    K.batch_set_value(weight_value_tuples)
  File "C:\carpeta_p_pycharm\M5_kaggle_accuracy\venv\lib\site-packages\tensorflow\python\keras\backend.py", line 3384, in batch_set_value
    x.assign(np.asarray(value, dtype=dtype(x)))
  File "C:\carpeta_p_pycharm\M5_kaggle_accuracy\venv\lib\site-packages\tensorflow\python\ops\resource_variable_ops.py", line 846, in assign
    self._shape.assert_is_compatible_with(value_tensor.shape)
  File "C:\carpeta_p_pycharm\M5_kaggle_accuracy\venv\lib\site-packages\tensorflow\python\framework\tensor_shape.py", line 1117, in assert_is_compatible_with
    raise ValueError("Shapes %s and %s are incompatible" % (self, other))
ValueError: Shapes (12, 12) and (12, 1) are incompatible

09.Jul 2020 13:24:49 evaluator module error
Shapes (8, 128) and (8, 12) are incompatible
Traceback (most recent call last):
  File ".\_4_evaluation.py", line 76, in evaluate
    classifier.load_weights(''.join([local_script_settings['models_path'], current_model_name, '_', str(date),
  File "C:\carpeta_p_pycharm\M5_kaggle_accuracy\venv\lib\site-packages\tensorflow\python\keras\engine\training.py", line 250, in load_weights
    return super(Model, self).load_weights(filepath, by_name, skip_mismatch)
  File "C:\carpeta_p_pycharm\M5_kaggle_accuracy\venv\lib\site-packages\tensorflow\python\keras\engine\network.py", line 1266, in load_weights
    hdf5_format.load_weights_from_hdf5_group(f, self.layers)
  File "C:\carpeta_p_pycharm\M5_kaggle_accuracy\venv\lib\site-packages\tensorflow\python\keras\saving\hdf5_format.py", line 707, in load_weights_from_hdf5_group
    K.batch_set_value(weight_value_tuples)
  File "C:\carpeta_p_pycharm\M5_kaggle_accuracy\venv\lib\site-packages\tensorflow\python\keras\backend.py", line 3384, in batch_set_value
    x.assign(np.asarray(value, dtype=dtype(x)))
  File "C:\carpeta_p_pycharm\M5_kaggle_accuracy\venv\lib\site-packages\tensorflow\python\ops\resource_variable_ops.py", line 846, in assign
    self._shape.assert_is_compatible_with(value_tensor.shape)
  File "C:\carpeta_p_pycharm\M5_kaggle_accuracy\venv\lib\site-packages\tensorflow\python\framework\tensor_shape.py", line 1117, in assert_is_compatible_with
    raise ValueError("Shapes %s and %s are incompatible" % (self, other))
ValueError: Shapes (8, 128) and (8, 12) are incompatible

09.Jul 2020 13:35:21 evaluator module error
Shapes (8, 1024) and (8, 12) are incompatible
Traceback (most recent call last):
  File ".\_4_evaluation.py", line 76, in evaluate
    classifier.load_weights(''.join([local_script_settings['models_path'], current_model_name, '_', str(date),
  File "C:\carpeta_p_pycharm\M5_kaggle_accuracy\venv\lib\site-packages\tensorflow\python\keras\engine\training.py", line 250, in load_weights
    return super(Model, self).load_weights(filepath, by_name, skip_mismatch)
  File "C:\carpeta_p_pycharm\M5_kaggle_accuracy\venv\lib\site-packages\tensorflow\python\keras\engine\network.py", line 1266, in load_weights
    hdf5_format.load_weights_from_hdf5_group(f, self.layers)
  File "C:\carpeta_p_pycharm\M5_kaggle_accuracy\venv\lib\site-packages\tensorflow\python\keras\saving\hdf5_format.py", line 707, in load_weights_from_hdf5_group
    K.batch_set_value(weight_value_tuples)
  File "C:\carpeta_p_pycharm\M5_kaggle_accuracy\venv\lib\site-packages\tensorflow\python\keras\backend.py", line 3384, in batch_set_value
    x.assign(np.asarray(value, dtype=dtype(x)))
  File "C:\carpeta_p_pycharm\M5_kaggle_accuracy\venv\lib\site-packages\tensorflow\python\ops\resource_variable_ops.py", line 846, in assign
    self._shape.assert_is_compatible_with(value_tensor.shape)
  File "C:\carpeta_p_pycharm\M5_kaggle_accuracy\venv\lib\site-packages\tensorflow\python\framework\tensor_shape.py", line 1117, in assert_is_compatible_with
    raise ValueError("Shapes %s and %s are incompatible" % (self, other))
ValueError: Shapes (8, 1024) and (8, 12) are incompatible

09.Jul 2020 13:46:04 evaluator module error
Shapes (8, 1024) and (8, 12) are incompatible
Traceback (most recent call last):
  File ".\_4_evaluation.py", line 76, in evaluate
    classifier.load_weights(''.join([local_script_settings['models_path'], current_model_name, '_', str(date),
  File "C:\carpeta_p_pycharm\M5_kaggle_accuracy\venv\lib\site-packages\tensorflow\python\keras\engine\training.py", line 250, in load_weights
    return super(Model, self).load_weights(filepath, by_name, skip_mismatch)
  File "C:\carpeta_p_pycharm\M5_kaggle_accuracy\venv\lib\site-packages\tensorflow\python\keras\engine\network.py", line 1266, in load_weights
    hdf5_format.load_weights_from_hdf5_group(f, self.layers)
  File "C:\carpeta_p_pycharm\M5_kaggle_accuracy\venv\lib\site-packages\tensorflow\python\keras\saving\hdf5_format.py", line 707, in load_weights_from_hdf5_group
    K.batch_set_value(weight_value_tuples)
  File "C:\carpeta_p_pycharm\M5_kaggle_accuracy\venv\lib\site-packages\tensorflow\python\keras\backend.py", line 3384, in batch_set_value
    x.assign(np.asarray(value, dtype=dtype(x)))
  File "C:\carpeta_p_pycharm\M5_kaggle_accuracy\venv\lib\site-packages\tensorflow\python\ops\resource_variable_ops.py", line 846, in assign
    self._shape.assert_is_compatible_with(value_tensor.shape)
  File "C:\carpeta_p_pycharm\M5_kaggle_accuracy\venv\lib\site-packages\tensorflow\python\framework\tensor_shape.py", line 1117, in assert_is_compatible_with
    raise ValueError("Shapes %s and %s are incompatible" % (self, other))
ValueError: Shapes (8, 1024) and (8, 12) are incompatible

09.Jul 2020 23:00:02 evaluator module error
Shapes (8, 12) and (8, 128) are incompatible
Traceback (most recent call last):
  File ".\_4_evaluation.py", line 76, in evaluate
    classifier.load_weights(''.join([local_script_settings['models_path'], current_model_name, '_', str(date),
  File "C:\carpeta_p_pycharm\M5_kaggle_accuracy\venv\lib\site-packages\tensorflow\python\keras\engine\training.py", line 250, in load_weights
    return super(Model, self).load_weights(filepath, by_name, skip_mismatch)
  File "C:\carpeta_p_pycharm\M5_kaggle_accuracy\venv\lib\site-packages\tensorflow\python\keras\engine\network.py", line 1266, in load_weights
    hdf5_format.load_weights_from_hdf5_group(f, self.layers)
  File "C:\carpeta_p_pycharm\M5_kaggle_accuracy\venv\lib\site-packages\tensorflow\python\keras\saving\hdf5_format.py", line 707, in load_weights_from_hdf5_group
    K.batch_set_value(weight_value_tuples)
  File "C:\carpeta_p_pycharm\M5_kaggle_accuracy\venv\lib\site-packages\tensorflow\python\keras\backend.py", line 3384, in batch_set_value
    x.assign(np.asarray(value, dtype=dtype(x)))
  File "C:\carpeta_p_pycharm\M5_kaggle_accuracy\venv\lib\site-packages\tensorflow\python\ops\resource_variable_ops.py", line 846, in assign
    self._shape.assert_is_compatible_with(value_tensor.shape)
  File "C:\carpeta_p_pycharm\M5_kaggle_accuracy\venv\lib\site-packages\tensorflow\python\framework\tensor_shape.py", line 1117, in assert_is_compatible_with
    raise ValueError("Shapes %s and %s are incompatible" % (self, other))
ValueError: Shapes (8, 12) and (8, 128) are incompatible
Number of classes, 4, does not match size of target_names, 12. Try specifying the labels parameter
Traceback (most recent call last):
  File ".\_4_evaluation.py", line 117, in evaluate
    print(classification_report(test_set.classes, y_predictions.argmax(axis=1), target_names=target_names))
  File "C:\carpeta_p_pycharm\M5_kaggle_accuracy\venv\lib\site-packages\sklearn\utils\validation.py", line 73, in inner_f
    return f(**kwargs)
  File "C:\carpeta_p_pycharm\M5_kaggle_accuracy\venv\lib\site-packages\sklearn\metrics\_classification.py", line 1950, in classification_report
    raise ValueError(
ValueError: Number of classes, 4, does not match size of target_names, 12. Try specifying the labels parameter
Only one class present in y_true. ROC AUC score is not defined in that case.
Traceback (most recent call last):
  File ".\_4_evaluation.py", line 137, in evaluate
    print('\n AUC_ROC score:', roc_auc_score(labels, no_hidden_message_prob))
  File "C:\carpeta_p_pycharm\M5_kaggle_accuracy\venv\lib\site-packages\sklearn\utils\validation.py", line 73, in inner_f
    return f(**kwargs)
  File "C:\carpeta_p_pycharm\M5_kaggle_accuracy\venv\lib\site-packages\sklearn\metrics\_ranking.py", line 390, in roc_auc_score
    return _average_binary_score(partial(_binary_roc_auc_score,
  File "C:\carpeta_p_pycharm\M5_kaggle_accuracy\venv\lib\site-packages\sklearn\metrics\_base.py", line 77, in _average_binary_score
    return binary_metric(y_true, y_score, sample_weight=sample_weight)
  File "C:\carpeta_p_pycharm\M5_kaggle_accuracy\venv\lib\site-packages\sklearn\metrics\_ranking.py", line 223, in _binary_roc_auc_score
    raise ValueError("Only one class present in y_true. ROC AUC score "
ValueError: Only one class present in y_true. ROC AUC score is not defined in that case.
Only one class present in y_true. ROC AUC score is not defined in that case.
Traceback (most recent call last):
  File ".\_4_evaluation.py", line 137, in evaluate
    print('\n AUC_ROC score:', roc_auc_score(labels, no_hidden_message_prob))
  File "C:\carpeta_p_pycharm\M5_kaggle_accuracy\venv\lib\site-packages\sklearn\utils\validation.py", line 73, in inner_f
    return f(**kwargs)
  File "C:\carpeta_p_pycharm\M5_kaggle_accuracy\venv\lib\site-packages\sklearn\metrics\_ranking.py", line 390, in roc_auc_score
    return _average_binary_score(partial(_binary_roc_auc_score,
  File "C:\carpeta_p_pycharm\M5_kaggle_accuracy\venv\lib\site-packages\sklearn\metrics\_base.py", line 77, in _average_binary_score
    return binary_metric(y_true, y_score, sample_weight=sample_weight)
  File "C:\carpeta_p_pycharm\M5_kaggle_accuracy\venv\lib\site-packages\sklearn\metrics\_ranking.py", line 223, in _binary_roc_auc_score
    raise ValueError("Only one class present in y_true. ROC AUC score "
ValueError: Only one class present in y_true. ROC AUC score is not defined in that case.
Only one class present in y_true. ROC AUC score is not defined in that case.
Traceback (most recent call last):
  File ".\_4_evaluation.py", line 137, in evaluate
    print('\n AUC_ROC score:', roc_auc_score(labels, no_hidden_message_prob))
  File "C:\carpeta_p_pycharm\M5_kaggle_accuracy\venv\lib\site-packages\sklearn\utils\validation.py", line 73, in inner_f
    return f(**kwargs)
  File "C:\carpeta_p_pycharm\M5_kaggle_accuracy\venv\lib\site-packages\sklearn\metrics\_ranking.py", line 390, in roc_auc_score
    return _average_binary_score(partial(_binary_roc_auc_score,
  File "C:\carpeta_p_pycharm\M5_kaggle_accuracy\venv\lib\site-packages\sklearn\metrics\_base.py", line 77, in _average_binary_score
    return binary_metric(y_true, y_score, sample_weight=sample_weight)
  File "C:\carpeta_p_pycharm\M5_kaggle_accuracy\venv\lib\site-packages\sklearn\metrics\_ranking.py", line 223, in _binary_roc_auc_score
    raise ValueError("Only one class present in y_true. ROC AUC score "
ValueError: Only one class present in y_true. ROC AUC score is not defined in that case.
Asked to retrieve element 0, but the Sequence has length 0
Traceback (most recent call last):
  File ".\_4_evaluation.py", line 108, in evaluate
    y_predictions = np.array(classifier.predict(test_set))
  File "C:\carpeta_p_pycharm\M5_kaggle_accuracy\venv\lib\site-packages\tensorflow\python\keras\engine\training.py", line 88, in _method_wrapper
    return method(self, *args, **kwargs)
  File "C:\carpeta_p_pycharm\M5_kaggle_accuracy\venv\lib\site-packages\tensorflow\python\keras\engine\training.py", line 1240, in predict
    data_handler = data_adapter.DataHandler(
  File "C:\carpeta_p_pycharm\M5_kaggle_accuracy\venv\lib\site-packages\tensorflow\python\keras\engine\data_adapter.py", line 1100, in __init__
    self._adapter = adapter_cls(
  File "C:\carpeta_p_pycharm\M5_kaggle_accuracy\venv\lib\site-packages\tensorflow\python\keras\engine\data_adapter.py", line 901, in __init__
    super(KerasSequenceAdapter, self).__init__(
  File "C:\carpeta_p_pycharm\M5_kaggle_accuracy\venv\lib\site-packages\tensorflow\python\keras\engine\data_adapter.py", line 772, in __init__
    peek, x = self._peek_and_restore(x)
  File "C:\carpeta_p_pycharm\M5_kaggle_accuracy\venv\lib\site-packages\tensorflow\python\keras\engine\data_adapter.py", line 912, in _peek_and_restore
    return x[0], x
  File "C:\carpeta_p_pycharm\M5_kaggle_accuracy\venv\lib\site-packages\keras_preprocessing\image\iterator.py", line 54, in __getitem__
    raise ValueError('Asked to retrieve element {idx}, '
ValueError: Asked to retrieve element 0, but the Sequence has length 0
error at folder_for_evaluation generation
Only one class present in y_true. ROC AUC score is not defined in that case.
Traceback (most recent call last):
  File ".\_4_evaluation.py", line 137, in evaluate
    print('\n AUC_ROC score:', roc_auc_score(labels, no_hidden_message_prob))
  File "C:\carpeta_p_pycharm\M5_kaggle_accuracy\venv\lib\site-packages\sklearn\utils\validation.py", line 73, in inner_f
    return f(**kwargs)
  File "C:\carpeta_p_pycharm\M5_kaggle_accuracy\venv\lib\site-packages\sklearn\metrics\_ranking.py", line 390, in roc_auc_score
    return _average_binary_score(partial(_binary_roc_auc_score,
  File "C:\carpeta_p_pycharm\M5_kaggle_accuracy\venv\lib\site-packages\sklearn\metrics\_base.py", line 77, in _average_binary_score
    return binary_metric(y_true, y_score, sample_weight=sample_weight)
  File "C:\carpeta_p_pycharm\M5_kaggle_accuracy\venv\lib\site-packages\sklearn\metrics\_ranking.py", line 223, in _binary_roc_auc_score
    raise ValueError("Only one class present in y_true. ROC AUC score "
ValueError: Only one class present in y_true. ROC AUC score is not defined in that case.
Only one class present in y_true. ROC AUC score is not defined in that case.
Traceback (most recent call last):
  File ".\_4_evaluation.py", line 138, in evaluate
    print('\n AUC_ROC score:', roc_auc_score(labels, no_hidden_message_prob))
  File "C:\carpeta_p_pycharm\M5_kaggle_accuracy\venv\lib\site-packages\sklearn\utils\validation.py", line 73, in inner_f
    return f(**kwargs)
  File "C:\carpeta_p_pycharm\M5_kaggle_accuracy\venv\lib\site-packages\sklearn\metrics\_ranking.py", line 390, in roc_auc_score
    return _average_binary_score(partial(_binary_roc_auc_score,
  File "C:\carpeta_p_pycharm\M5_kaggle_accuracy\venv\lib\site-packages\sklearn\metrics\_base.py", line 77, in _average_binary_score
    return binary_metric(y_true, y_score, sample_weight=sample_weight)
  File "C:\carpeta_p_pycharm\M5_kaggle_accuracy\venv\lib\site-packages\sklearn\metrics\_ranking.py", line 223, in _binary_roc_auc_score
    raise ValueError("Only one class present in y_true. ROC AUC score "
ValueError: Only one class present in y_true. ROC AUC score is not defined in that case.
Only one class present in y_true. ROC AUC score is not defined in that case.
Traceback (most recent call last):
  File ".\_4_evaluation.py", line 138, in evaluate
    print('\n AUC_ROC score:', roc_auc_score(labels, no_hidden_message_prob))
  File "C:\carpeta_p_pycharm\M5_kaggle_accuracy\venv\lib\site-packages\sklearn\utils\validation.py", line 73, in inner_f
    return f(**kwargs)
  File "C:\carpeta_p_pycharm\M5_kaggle_accuracy\venv\lib\site-packages\sklearn\metrics\_ranking.py", line 390, in roc_auc_score
    return _average_binary_score(partial(_binary_roc_auc_score,
  File "C:\carpeta_p_pycharm\M5_kaggle_accuracy\venv\lib\site-packages\sklearn\metrics\_base.py", line 77, in _average_binary_score
    return binary_metric(y_true, y_score, sample_weight=sample_weight)
  File "C:\carpeta_p_pycharm\M5_kaggle_accuracy\venv\lib\site-packages\sklearn\metrics\_ranking.py", line 223, in _binary_roc_auc_score
    raise ValueError("Only one class present in y_true. ROC AUC score "
ValueError: Only one class present in y_true. ROC AUC score is not defined in that case.
